<?xml version="1.0"?>
<robot xmlns:xacro="http://www.ros.org/wiki/xacro">
    <xacro:include filename="$(find fishbot_description)/urdf/fishbot/common_inertia.xacro" />
    <xacro:macro name="wheel_xacro" params="wheel_name xyz">

        <gazebo reference="${wheel_name}_wheel_link">
            <material>Gazebo/Black</material>
        </gazebo>

        <link name="${wheel_name}_wheel_link">
            <visual>
                <!-- xyz="0 0 0"：表示该几何体的原点坐标 -->
                <!-- rpy="1.57079 0 0"：表示该几何体的姿态（旋转），使用的是滚转（Roll）、俯仰（Pitch）、偏航（Yaw）角 -->
                <origin xyz="0 0 0" rpy="1.57079 0 0" />
                <geometry>
                    <cylinder length="0.04" radius="0.032" />
                </geometry>
                <material name="yellow">
                    <color rgba="1.0 1.0 0.0 0.8"/>
                </material>
            </visual>
            <collision>
                <origin xyz="0 0 0" rpy="1.57079 0 0" />
                <geometry>
                    <cylinder length="0.04" radius="0.032" />
                </geometry>
                <material name="yellow">
                    <color rgba="1.0 1.0 0.0 0.8"/>
                </material>
            </collision>
            <xacro:cylinder_inertia m="0.1" h="0.04" r="0.032"/>
        </link>
        <!-- 切向摩擦，法向摩擦；接触刚度系数，阻尼系数 -->
        <gazebo reference="${wheel_name}_wheel_link">
            <mu1 value="10.0" />
            <mu2 value="20.0" />
            <kp value="1000000000.0" />
            <kd value="1.5" />
        </gazebo>

        <joint name="${wheel_name}_wheel_joint" type="continuous">
            <parent link="base_link" />
            <child link="${wheel_name}_wheel_link" />
            <origin xyz="${xyz}" />
            <!-- 绕y轴正方向旋转 -->
            <axis xyz="0 1 0" />
        </joint>
    </xacro:macro>
</robot>